Workbook

Sheet Paises
A1: id | B1: country_name | C1: fifa_ranking | D1: points | E1: pct_ranking | F1: máx. | G1: =MAX((D2:D212))
A2: 1 | B2: Argentina | C2: 1 | D2: 1876.12 | E2: =(D2/G$1)
A3: 2 | B3: Spain | C3: 2 | D3: 1874.71 | E3: =(D3/G$1)
A4: 3 | B4: France | C4: 3 | D4: 1870.7 | E4: =(D4/G$1)
A5: 4 | B5: England | C5: 4 | D5: 1827.05 | E5: =(D5/G$1)
A6: 5 | B6: Portugal | C6: 5 | D6: 1766.18 | E6: =(D6/G$1)
A7: 6 | B7: Brazil | C7: 6 | D7: 1765.86 | E7: =(D7/G$1)
A8: 7 | B8: Morocco | C8: 7 | D8: 1755.1 | E8: =(D8/G$1)
A9: 8 | B9: Netherlands | C9: 8 | D9: 1753.57 | E9: =(D9/G$1)
A10: 9 | B10: Belgium | C10: 9 | D10: 1742.24 | E10: =(D10/G$1)
A11: 10 | B11: Germany | C11: 10 | D11: 1735.77 | E11: =(D11/G$1)
A12: 11 | B12: Croatia | C12: 11 | D12: 1714.87 | E12: =(D12/G$1)
A13: 12 | B13: Italy | C13: 12 | D13: 1704.73 | E13: =(D13/G$1)
... A212: 211 | B212: San Marino | C212: 211 | D212: 722.93 | E212: =(D212/G$1)

Sheet Selecoes
A1: id | B1: pais | C1: grupo | D1: sistema _tatico
A2: 1 | B2: Mexico | C2: Group A | D2: 1 | E2: 4 | F2: 3 | G2: 3
A3: 2 | B3: South Africa | C3: Group A | D3: 1 | E3: 5 | F3: 3 | G3: 2
A4: 3 | B4: Korea Republic | C4: Group A | D4: 1 | E4: 3 | F4: 4 | G4: 3
A5: 4 | B5: Czechia | C5: Group A | D5: 1 | E5: 3 | F5: 4 | G5: 3
A6: 5 | B6: Canada | C6: Group B | D6: 1 | E6: 4 | F6: 4 | G6: 2
A7: 6 | B7: Bosnia and Herzegovina | C7: Group B | D7: 1 | E7: 4 | F7: 4 | G7: 2
A8: 7 | B8: Qatar | C8: Group B | D8: 1 | E8: 4 | F8: 3 | G8: 3
A9: 8 | B9: Switzerland | C9: Group B | D9: 1 | E9: 4 | F9: 5 | G9: 1
A10: 9 | B10: Brazil | C10: Group C | D10: 1 | E10: 4 | F10: 3 | G10: 3
A11: 10 | B11: Morocco | C11: Group C | D11: 1 | E11: 4 | F11: 3 | G11: 3
A12: 11 | B12: Haiti | C12: Group C | D12: 1 | E12: 4 | F12: 4 | G12: 2
A13: 12 | B13: Scotland | C13: Group C | D13: 1 | E13: 4 | F13: 4 | G13: 2
... A49: 48 | B49: Panama | C49: Group L | D49: 1 | E49: 4 | F49: 3 | G49: 3

Sheet Jogadores
A1: id_jogador | B1: pais | C1: jogador | D1: posicao | E1: clube | F1: liga | G1: pais_liga | H1: jogos_possiveis_clube | I1: jogos_jogador | J1: pct_jogos | K1: minutos_possiveis_clube | L1: minutos_jogador | M1: pct_minutos
A2: 1 | B2: South Africa | C2: Ronwen Williams | D2: Guarda Redes | E2: Sundowns | F2: =VLOOKUP(E2,Clubes!B$2:D$438,2) | G2: =VLOOKUP(E2,Clubes!B$2:D$438,3) | H2: 30 | J2: =I2/H2 | K2: =H2*90 | M2: =L2/K2
A3: 2 | B3: South Africa | C3: Sipho Chaine | D3: Guarda Redes | E3: Orlando Pirates | F3: =VLOOKUP(E3,Clubes!B$2:D$438,2) | G3: =VLOOKUP(E3,Clubes!B$2:D$438,3) | H3: 30 | J3: =I3/H3 | K3: =H3*90 | M3: =L3/K3
A4: 3 | B4: South Africa | C4: Ricardo Goss | D4: Guarda Redes | E4: Siwelele | F4: =VLOOKUP(E4,Clubes!B$2:D$438,2) | G4: =VLOOKUP(E4,Clubes!B$2:D$438,3) | H4: 30 | J4: =I4/H4 | K4: =H4*90 | M4: =L4/K4
A5: 4 | B5: South Africa | C5: Tholo Matuludi | D5: Defesa | E5: Polokwane City | F5: =VLOOKUP(E5,Clubes!B$2:D$438,2) | G5: =VLOOKUP(E5,Clubes!B$2:D$438,3) | H5: 30 | J5: =I5/H5 | K5: =H5*90 | M5: =L5/K5
A6: 5 | B6: South Africa | C6: Khuliso Mudau | D6: Defesa | E6: Sundowns | F6: =VLOOKUP(E6,Clubes!B$2:D$438,2) | G6: =VLOOKUP(E6,Clubes!B$2:D$438,3) | H6: 30 | J6: =I6/H6 | K6: =H6*90 | M6: =L6/K6
A7: 6 | B7: South Africa | C7: Kulumani Ndamane | D7: Defesa | E7: Sundowns | F7: =VLOOKUP(E7,Clubes!B$2:D$438,2) | G7: =VLOOKUP(E7,Clubes!B$2:D$438,3) | H7: 30 | J7: =I7/H7 | K7: =H7*90 | M7: =L7/K7
A8: 7 | B8: South Africa | C8: Mbekezeli Mbokazi | D8: Defesa | E8: Chicago Fire | F8: =VLOOKUP(E8,Clubes!B$2:D$438,2) | G8: =VLOOKUP(E8,Clubes!B$2:D$438,3) | H8: 34 | J8: =I8/H8 | K8: =H8*90 | M8: =L8/K8
A9: 8 | B9: South Africa | C9: Samukele Kabini | D9: Defesa | E9: Molde | F9: =VLOOKUP(E9,Clubes!B$2:D$438,2) | G9: =VLOOKUP(E9,Clubes!B$2:D$438,3) | H9: 30 | J9: =I9/H9 | K9: =H9*90 | M9: =L9/K9
A10: 9 | B10: South Africa | C10: Nkosinathi Sibisi | D10: Defesa | E10: Orlando Pirates | F10: =VLOOKUP(E10,Clubes!B$2:D$438,2) | G10: =VLOOKUP(E10,Clubes!B$2:D$438,3) | H10: 30 | J10: =I10/H10 | K10: =H10*90 | M10: =L10/K10
A11: 10 | B11: South Africa | C11: Ime Okon | D11: Defesa | E11: Hannover 96 | F11: =VLOOKUP(E11,Clubes!B$2:D$438,2) | G11: =VLOOKUP(E11,Clubes!B$2:D$438,3) | H11: 34 | J11: =I11/H11 | K11: =H11*90 | M11: =L11/K11
A12: 11 | B12: South Africa | C12: Olwethu Makhanya | D12: Defesa | E12: Philadelphia Union | F12: =VLOOKUP(E12,Clubes!B$2:D$438,2) | G12: =VLOOKUP(E12,Clubes!B$2:D$438,3) | H12: 34 | J12: =I12/H12 | K12: =H12*90 | M12: =L12/K12
A13: 12 | B13: South Africa | C13: Bradley Cross | D13: Defesa | E13: Kaizer Chiefs | F13: =VLOOKUP(E13,Clubes!B$2:D$438,2) | G13: =VLOOKUP(E13,Clubes!B$2:D$438,3) | H13: 30 | J13: =I13/H13 | K13: =H13*90 | M13: =L13/K13
... A813: 812 | B813: Iraq | C813: Frans Putros | D813: Defesa | E813: Persib Bandung | F813: =VLOOKUP(E813,Clubes!B$2:D$438,2) | G813: =VLOOKUP(E813,Clubes!B$2:D$438,3) | H813: 34 | J813: =I813/H813 | K813: =H813*90 | M813: =L813/K813
A814: 813 | B814: Iraq | C814: Ahmed Yahia | D814: Defesa | F814: =VLOOKUP(E814,Clubes!B$2:D$438,2) | G814: =VLOOKUP(E814,Clubes!B$2:D$438,3) | J814: =I814/H814 | K814: =H814*90 | M814: =L814/K814
A815: 814 | B815: Iraq | C815: Maytham Jabbar | D815: Defesa | E815: Al-Zawra´a | F815: =VLOOKUP(E815,Clubes!B$2:D$438,2) | G815: =VLOOKUP(E815,Clubes!B$2:D$438,3) | H815: 38 | J815: =I815/H815 | K815: =H815*90 | M815: =L815/K815
A816: 815 | B816: Iraq | C816: Hussein Ali | D816: Defesa | E816: Pogon Szczecin | F816: =VLOOKUP(E816,Clubes!B$2:D$438,2) | G816: =VLOOKUP(E816,Clubes!B$2:D$438,3) | H816: 34 | J816: =I816/H816 | K816: =H816*90 | M816: =L816/K816
A817: 816 | B817: Iraq | C817: Zaid Tahseen | D817: Defesa | E817: Al-Quwa Al-Jawiya | F817: =VLOOKUP(E817,Clubes!B$2:D$438,2) | G817: =VLOOKUP(E817,Clubes!B$2:D$438,3) | H817: 38 | J817: =I817/H817 | K817: =H817*90 | M817: =L817/K817
A818: 817 | B818: Iraq | C818: Akam Hashim | D818: Defesa | E818: Al-Zawra´a | F818: =VLOOKUP(E818,Clubes!B$2:D$438,2) | G818: =VLOOKUP(E818,Clubes!B$2:D$438,3) | H818: 38 | J818: =I818/H818 | K818: =H818*90 | M818: =L818/K818
A819: 818 | B819: Iraq | C819: Mustafa Saadoun | D819: Defesa | E819: Al-Quwa Al-Jawiya | F819: =VLOOKUP(E819,Clubes!B$2:D$438,2) | G819: =VLOOKUP(E819,Clubes!B$2:D$438,3) | H819: 38 | J819: =I819/H819 | K819: =H819*90 | M819: =L819/K819
A820: 819 | B820: Iraq | C820: Ahmed Yahya | D820: Defesa | E820: Al-Shorta Bagdad | F820: =VLOOKUP(E820,Clubes!B$2:D$438,2) | G820: =VLOOKUP(E820,Clubes!B$2:D$438,3) | H820: 38 | J820: =I820/H820 | K820: =H820*90 | M820: =L820/K820
A821: 820 | B821: Iraq | C821: Rebin Sulaka | D821: Defesa | E821: Port FC | F821: =VLOOKUP(E821,Clubes!B$2:D$438,2) | G821: =VLOOKUP(E821,Clubes!B$2:D$438,3) | H821: 30 | J821: =I821/H821 | K821: =H821*90 | M821: =L821/K821
A822: 821 | B822: Iraq | C822: Ahmad Hasan | D822: Defesa | E822: Al-Karma | F822: =VLOOKUP(E822,Clubes!B$2:D$438,2) | G822: =VLOOKUP(E822,Clubes!B$2:D$438,3) | H822: 38 | J822: =I822/H822 | K822: =H822*90 | M822: =L822/K822
A823: 822 | B823: Iraq | C823: Manaf Younis | D823: Defesa | E823: Al-Shorta Bagdad | F823: =VLOOKUP(E823,Clubes!B$2:D$438,2) | G823: =VLOOKUP(E823,Clubes!B$2:D$438,3) | H823: 38 | J823: =I823/H823 | K823: =H823*90 | M823: =L823/K823
A824: 823 | B824: Iraq | C824: Merchas Doski | D824: Defesa | E824: Viktoria Plzeň | F824: =VLOOKUP(E824,Clubes!B$2:D$438,2) | G824: =VLOOKUP(E824,Clubes!B$2:D$438,3) | H824: 35 | J824: =I824/H824 | K824: =H824*90 | M824: =L824/K824
A825: 824 | B825: Iraq | C825: Dario Naamo | D825: Defesa | E825: Dundee United | F825: =VLOOKUP(E825,Clubes!B$2:D$438,2) | G825: =VLOOKUP(E825,Clubes!B$2:D$438,3) | H825: 38 | J825: =I825/H825 | K825: =H825*90 | M825: =L825/K825
A826: 825 | B826: Iraq | C826: Amir Al-Ammari | D826: Médio | E826: KS Cracovia | F826: =VLOOKUP(E826,Clubes!B$2:D$438,2) | G826: =VLOOKUP(E826,Clubes!B$2:D$438,3) | H826: 34 | J826: =I826/H826 | K826: =H826*90 | M826: =L826/K826
... A1294: 1318 | B1294: Uzbekistan | C1294: Jaloliddin Masharipov | D1294: Avançado | E1294: Esteghlal Tehran | F1294: =VLOOKUP(E1294,Clubes!B$2:D$438,2) | G1294: =VLOOKUP(E1294,Clubes!B$2:D$438,3) | H1294: 30 | J1294: =I1294/H1294 | K1294: =H1294*90 | M1294: =L1294/K1294

Sheet Clubes
A1: id_clube | B1: clube | C1: liga | D1: pais_liga | E1: ocorrencias | F1: confianca | G1: posisacao_equipa | H1: epoca_alvo
A2: 1 | B2: 1. FC Union Berlin | C2: Bundesliga | D2: Germany | E2: 1 | F2: Alta | G2: 11 | H2: 2025/26 | I2: confirmado_por_zerozero_screenshot | J2: ZeroZero screenshot enviado pelo utilizador - Bundesliga 2025/26 | K2: Validado com a classificação visível no screenshot enviado. Clube normalizado: 1. FC Union Berlin -> 1 fc union berlin.
A3: 2 | B3: AEK | C3: Super League Greece | D3: Greece | E3: 1 | F3: Alta | G3: 1 | H3: 2025/26 | I3: confirmado_por_zerozero_screenshot_v5 | J3: ZeroZero screenshot enviado pelo utilizador - Super League Greece 2025/26 | K3: Validado com screenshot ZeroZero enviado nesta passagem. Clube normalizado: AEK -> aek.
A4: 3 | B4: AEK Larnaca | C4: Cypriot First Division | D4: Cyprus | E4: 1 | F4: Alta | G4: 2 | H4: 2025/26 | I4: confirmado_por_zerozero_screenshot_v5 | J4: ZeroZero screenshot enviado pelo utilizador - Cypriot First Division 2025/26 | K4: Validado com screenshot ZeroZero enviado nesta passagem. Clube normalizado: AEK Larnaca -> aek larnaca.
A5: 4 | B5: AEL Limassol | C5: Cypriot First Division | D5: Cyprus | E5: 2 | F5: Alta | G5: 8 | H5: 2025/26 | I5: confirmado_por_zerozero_screenshot_v5 | J5: ZeroZero screenshot enviado pelo utilizador - Cypriot First Division 2025/26 | K5: Validado com screenshot ZeroZero enviado nesta passagem. Clube normalizado: AEL Limassol -> ael limassol.
A6: 5 | B6: AGF Aarhus | C6: Danish Superliga | D6: Denmark | E6: 1 | F6: Alta | G6: 1 | H6: 2025/26 | I6: confirmado_por_zerozero_screenshot | J6: ZeroZero screenshot enviado pelo utilizador - Superligaen fase regular 2025/26 | K6: Validado com a classificação visível no screenshot enviado. Clube normalizado: AGF Aarhus -> agf aarhus.
A7: 6 | B7: AIK | C7: Allsvenskan | D7: Sweden | E7: 1 | F7: Alta | G7: 10 | H7: 2026 | I7: confirmado_por_zerozero_screenshot_v9 | J7: ZeroZero screenshot enviado pelo utilizador - Allsvenskan 2026 | K7: Validado com screenshot ZeroZero enviado nesta passagem. Clube normalizado: AIK -> aik.
A8: 7 | B8: APOEL | C8: Cypriot First Division | D8: Cyprus | E8: 1 | F8: Alta | G8: 5 | H8: 2025/26 | I8: confirmado_por_zerozero_screenshot_v5 | J8: ZeroZero screenshot enviado pelo utilizador - Cypriot First Division 2025/26 | K8: Validado com screenshot ZeroZero enviado nesta passagem. Clube normalizado: APOEL -> apoel.
A9: 8 | B9: AZ Alkmaar | C9: Eredivisie | D9: Netherlands | E9: 1 | F9: Alta | G9: 7 | H9: 2025/26 | I9: confirmado_por_zerozero_screenshot | J9: ZeroZero screenshot enviado pelo utilizador - Eredivisie 2025/26 | K9: Validado com a classificação visível no screenshot enviado. Clube normalizado: AZ Alkmaar -> az alkmaar.
A10: 9 | B10: Abha Club | C10: Saudi First Division League | D10: Saudi Arabia | E10: 1 | F10: Média | G10: 1 | H10: 2025/26 | I10: confirmado_por_zerozero_screenshot_v9 | J10: ZeroZero screenshot enviado pelo utilizador - Yelo League 2025/26 | K10: Validado com screenshot ZeroZero enviado nesta passagem. Clube normalizado: Abha Club -> abha club.
A11: 10 | B11: Ajax | C11: Eredivisie | D11: Netherlands | E11: 5 | F11: Alta | G11: 5 | H11: 2025/26 | I11: confirmado_por_zerozero_screenshot | J11: ZeroZero screenshot enviado pelo utilizador - Eredivisie 2025/26 | K11: Validado com a classificação visível no screenshot enviado. Clube normalizado: Ajax -> ajax.
A12: 11 | B12: Akron Togliatti | C12: Russian Premier League | D12: Russia | E12: 1 | F12: Alta | G12: 13 | H12: 2025/26 | I12: confirmado_por_zerozero_screenshot_v5 | J12: ZeroZero screenshot enviado pelo utilizador - Russian Premier League 2025/26 | K12: Validado com screenshot ZeroZero enviado nesta passagem. Clube normalizado: Akron Togliatti -> akron togliatti.
A13: 12 | B13: Al Ahli | C13: Qatar Stars League | D13: Qatar | E13: 1 | F13: Alta | G13: 9 | H13: 2025/26 | I13: confirmado_por_zerozero_screenshot_v5 | J13: ZeroZero screenshot enviado pelo utilizador - Stars League Qatar 2025/26 | K13: Validado com screenshot ZeroZero enviado nesta passagem. Clube normalizado: Al Ahli -> al ahli.
A14: 13 | B14: Al Ain | C14: UAE Pro League | D14: United Arab Emirates | E14: 3 | F14: Alta | G14: 1 | H14: 2025/26 | I14: confirmado_por_zerozero_screenshot_v5 | J14: ZeroZero screenshot enviado pelo utilizador - Arabian Gulf League 2025/26 | K14: Validado com screenshot ZeroZero enviado nesta passagem. Clube normalizado: Al Ain -> al ain.
A15: 14 | B15: Al Bataeh | C15: UAE Pro League | D15: United Arab Emirates | E15: 2 | F15: Alta | G15: 13 | H15: 2025/26 | I15: confirmado_por_zerozero_screenshot_v5 | J15: ZeroZero screenshot enviado pelo utilizador - Arabian Gulf League 2025/26 | K15: Validado com screenshot ZeroZero enviado nesta passagem. Clube normalizado: Al Bataeh -> al bataeh.
A16: 15 | B16: Al Dhafra | C16: UAE First Division League | D16: United Arab Emirates | E16: 1 | F16: Média | G16: 12 | H16: 2025/26 | I16: confirmado_por_screenshot_v10 | J16: Screenshot enviado pelo utilizador - Arabian Gulf League 2025/26 (usado para validar Al Dhafra; nome da liga no dataset diverge) | K16: Validado com screenshot enviado nesta passagem. O dataset traz a liga como 'UAE First Division League', mas o screenshot fornecido mostra 'Arabian Gulf League 2025/26'. O clube Al Dhafra aparece na tabela na posição 12; valor preenchido com esta ressalva.
A17: 16 | B17: Al Ittihad Kalba | C17: UAE Pro League | D17: United Arab Emirates | E17: 2 | F17: Alta | G17: 11 | H17: 2025/26 | I17: confirmado_por_zerozero_screenshot_v5 | J17: ZeroZero screenshot enviado pelo utilizador - Arabian Gulf League 2025/26 | K17: Validado com screenshot ZeroZero enviado nesta passagem. Clube normalizado: Al Ittihad Kalba -> al ittihad kalba.
A18: 17 | B18: Al Jazira | C18: UAE Pro League | D18: United Arab Emirates | E18: 1 | F18: Alta | G18: 4 | H18: 2025/26 | I18: confirmado_por_zerozero_screenshot_v5 | J18: ZeroZero screenshot enviado pelo utilizador - Arabian Gulf League 2025/26 | K18: Validado com screenshot ZeroZero enviado nesta passagem. Clube normalizado: Al Jazira -> al jazira.
A19: 18 | B19: Al Wahda | C19: UAE Pro League | D19: United Arab Emirates | E19: 1 | F19: Alta | G19: 5 | H19: 2025/26 | I19: confirmado_por_zerozero_screenshot_v5 | J19: ZeroZero screenshot enviado pelo utilizador - Arabian Gulf League 2025/26 | K19: Validado com screenshot ZeroZero enviado nesta passagem. Clube normalizado: Al Wahda -> al wahda.
... A45: 44 | B45: Alanyaspor | C45: Süper Lig | D45: Turkey | E45: 1 | F45: Alta | G45: 11 | H45: 2025/26 | I45: confirmado_por_zerozero_screenshot | J45: ZeroZero screenshot enviado pelo utilizador - Süper Lig 2025/26 | K45: Validado com a classificação visível no screenshot enviado. Clube normalizado: Alanyaspor -> alanyaspor.
A46: 45 | B46: Albirex Niigata | C46: J1 League | D46: Japan | E46: 1 | F46: Alta | G46: 20 | H46: 2026 | I46: confirmado_por_zerozero_screenshot_v6 | J46: ZeroZero screenshot enviado pelo utilizador - J1 League 2026 | K46: Validado com screenshot ZeroZero enviado nesta passagem. Clube normalizado: Albirex Niigata -> albirex niigata.
A47: 46 | B47: Almere City FC | C47: Eerste Divisie | D47: Netherlands | E47: 1 | F47: Alta | G47: 5 | H47: 2025/26 | I47: confirmado_por_zerozero_screenshot_v9 | J47: ZeroZero screenshot enviado pelo utilizador - Eerste Divisie 2025/26 | K47: Validado com screenshot ZeroZero enviado nesta passagem. Clube normalizado: Almere City FC -> almere city fc.
A48: 47 | B48: Anderlecht | C48: Belgian Pro League | D48: Belgium | E48: 2 | F48: Alta | G48: 6 | H48: 2025/26 | I48: confirmado_por_zerozero_screenshot | J48: ZeroZero screenshot enviado pelo utilizador - Jupiler Pro League fase regular 2025/26 | K48: Validado com a classificação visível no screenshot enviado. Clube normalizado: Anderlecht -> anderlecht.
A49: 48 | B49: Angers | C49: Ligue 1 | D49: France | E49: 1 | F49: Alta | G49: 13 | H49: 2025/26 | I49: confirmado_por_zerozero_screenshot | J49: ZeroZero screenshot enviado pelo utilizador - Ligue 1 2025/26 | K49: Validado com a classificação visível no screenshot enviado. Clube normalizado: Angers -> angers.
A50: 49 | B50: Apollon Limassol | C50: Cypriot First Division | D50: Cyprus | E50: 1 | F50: Alta | G50: 3 | H50: 2025/26 | I50: confirmado_por_zerozero_screenshot_v5 | J50: ZeroZero screenshot enviado pelo utilizador - Cypriot First Division 2025/26 | K50: Validado com screenshot ZeroZero enviado nesta passagem. Clube normalizado: Apollon Limassol -> apollon limassol.
A51: 50 | B51: Aris Limassol | C51: Cypriot First Division | D51: Cyprus | E51: 1 | F51: Alta | G51: 6 | H51: 2025/26 | I51: confirmado_por_zerozero_screenshot_v5 | J51: ZeroZero screenshot enviado pelo utilizador - Cypriot First Division 2025/26 | K51: Validado com screenshot ZeroZero enviado nesta passagem. Clube normalizado: Aris Limassol -> aris limassol.
A52: 51 | B52: Arsenal | C52: Premier League | D52: England | E52: 17 | F52: Alta | G52: 1 | H52: 2025/26 | I52: confirmado_por_zerozero_screenshot | J52: ZeroZero screenshot enviado pelo utilizador - Premier League 2025/26 | K52: Validado com a classificação visível no screenshot enviado. Clube normalizado: Arsenal -> arsenal.
A53: 52 | B53: Astana | C53: Kazakhstan Premier League | D53: Kazakhstan | E53: 1 | F53: Alta | G53: 5 | H53: 2026 | I53: confirmado_por_screenshot_v10 | J53: Screenshot ZeroZero enviado pelo utilizador - Premier Liga 2026 | K53: Validado com screenshot enviado nesta passagem.
A54: 53 | B54: Aston Villa | C54: Premier League | D54: England | E54: 9 | F54: Alta | G54: 4 | H54: 2025/26 | I54: confirmado_por_zerozero_screenshot | J54: ZeroZero screenshot enviado pelo utilizador - Premier League 2025/26 | K54: Validado com a classificação visível no screenshot enviado. Clube normalizado: Aston Villa -> aston villa.
A55: 54 | B55: Atalanta | C55: Serie A | D55: Italy | E55: 9 | F55: Alta | G55: 7 | H55: 2025/26 | I55: confirmado_por_zerozero_screenshot | J55: ZeroZero screenshot enviado pelo utilizador - Serie A 2025/26 | K55: Validado com a classificação visível no screenshot enviado. Clube normalizado: Atalanta -> atalanta.
A56: 55 | B56: Athletic Bilbao | C56: LaLiga | D56: Spain | E56: 4 | F56: Alta | G56: 12 | H56: 2025/26 | I56: confirmado_por_zerozero_screenshot | J56: ZeroZero screenshot enviado pelo utilizador - LaLiga 2025/26 | K56: Validado com a classificação visível no screenshot enviado. Clube normalizado: Athletic Bilbao -> athletic bilbao.
A57: 56 | B57: Athletico Paranaense | C57: Campeonato Brasileiro Série B | D57: Brazil | E57: 1 | F57: Alta | G57: 4 | H57: 2026 | I57: por_validar_sem_screenshot_da_liga | K57: Não preenchido: falta screenshot/tabela da liga Campeonato Brasileiro Série B na época 2026, ou clube não aparece na tabela enviada.
A58: 57 | B58: Atlanta United | C58: Major League Soccer | D58: United States/Canada | E58: 2 | F58: Alta | G58: 14 | H58: 2026 | I58: confirmado_por_zerozero_screenshot | J58: ZeroZero screenshot enviado pelo utilizador - MLS 2026, posição na conferência | K58: Validado com a classificação visível no screenshot enviado. Clube normalizado: Atlanta United -> atlanta united.
A59: 58 | B59: Atlas | C59: Liga MX | D59: Mexico | E59: 1 | F59: Alta | G59: 6 | H59: 2026 | I59: confirmado_por_zerozero_screenshot_v6 | J59: ZeroZero screenshot enviado pelo utilizador - Liga MX Clausura 2026 aplicado a Liga MX | K59: Validado com screenshot ZeroZero enviado nesta passagem. Clube normalizado: Atlas -> atlas.
A60: 59 | B60: Atlético Mineiro | C60: Campeonato Brasileiro Série A | D60: Brazil | E60: 4 | F60: Alta | G60: 9 | H60: 2026 | I60: confirmado_por_zerozero_screenshot | J60: ZeroZero screenshot enviado pelo utilizador - Brasileirão Série A 2026 | K60: Validado com a classificação visível no screenshot enviado. Clube normalizado: Atlético Mineiro -> atletico mineiro.
A61: 60 | B61: Atlético Nacional | C61: Categoría Primera A | D61: Colombia | E61: 1 | F61: Alta | G61: 1 | H61: 2026 | I61: confirmado_por_screenshot_v10 | J61: Screenshot Flashscore enviado pelo utilizador - Primera A Apertura 2026 | K61: Validado com screenshot enviado nesta passagem.
A62: 61 | B62: Atlético de Madrid | C62: LaLiga | D62: Spain | E62: 12 | F62: Alta | G62: 4 | H62: 2025/26 | I62: confirmado_por_zerozero_screenshot | J62: ZeroZero screenshot enviado pelo utilizador - LaLiga 2025/26 | K62: Validado com a classificação visível no screenshot enviado. Clube normalizado: Atlético de Madrid -> atletico madrid.
A63: 62 | B63: Atromitos | C63: Super League Greece | D63: Greece | E63: 1 | F63: Alta | G63: 9 | H63: 2025/26 | I63: confirmado_por_zerozero_screenshot_v5 | J63: ZeroZero screenshot enviado pelo utilizador - Super League Greece 2025/26 | K63: Validado com screenshot ZeroZero enviado nesta passagem. Clube normalizado: Atromitos -> atromitos.
A64: 63 | B64: Auckland FC | C64: A-League Men | D64: Australia/New Zealand | E64: 5 | F64: Alta | G64: 3 | H64: 2025/26 | I64: confirmado_por_zerozero_screenshot_v6 | J64: ZeroZero screenshot enviado pelo utilizador - A-League Men 2025/26 | K64: Validado com screenshot ZeroZero enviado nesta passagem. Clube normalizado: Auckland FC -> auckland fc.
A65: 64 | B65: Austria Wien | C65: Austrian Bundesliga | D65: Austria | E65: 1 | F65: Alta | G65: 4 | H65: 2025/26 | I65: confirmado_por_zerozero_screenshot_v7 | J65: ZeroZero screenshots enviados pelo utilizador - Austrian Bundesliga 2025/26 Meistergruppe + regular | K65: Validado com screenshot ZeroZero enviado nesta passagem. Clube normalizado: Austria Wien -> austria wien.
...

Sheet Stats_Clube
A1: id | B1: pais_jogador | C1: jogador | D1: posicao | E1: clube | F1: liga | G1: pais_liga | H1: jogos_possiveis_clube | I1: jogos_jogador | J1: pct_jogos | K1: minutos_possiveis_clube | L1: minutos_jogador | M1: pct_minutos | N1: source_url | O1: created_at | P1: updated_at
A2: 1 | B2: South Africa | C2: Ronwen Williams | D2: Guarda Redes | E2: Sundowns | F2: South African Premiership | G2: South Africa | H2: 30 | I2: 29 | J2: =IFERROR(I2/H2,"") | K2: 2700 | L2: 2610 | M2: =IFERROR(L2/K2,"") | N2: Transfermarkt - Betway Premiership 25/26 clean sheets / matches / minutes | O2: confirmado | P2: Ronwen Williams: 29 jogos, 2610 minutos.
A3: 2 | B3: South Africa | C3: Sipho Chaine | D3: Guarda Redes | E3: Orlando Pirates | F3: South African Premiership | G3: South Africa | H3: 30 | I3: 30 | J3: =IFERROR(I3/H3,"") | K3: 2700 | L3: 2700 | M3: =IFERROR(L3/K3,"") | N3: Transfermarkt - Betway Premiership 25/26 clean sheets / matches / minutes | O3: confirmado | P3: Sipho Chaine: 30 jogos, 2700 minutos.
A4: 3 | B4: South Africa | C4: Ricardo Goss | D4: Guarda Redes | E4: Siwelele | F4: South African Premiership | G4: South Africa | H4: 30 | I4: 29 | J4: =IFERROR(I4/H4,"") | K4: 2700 | L4: 2610 | M4: =IFERROR(L4/K4,"") | N4: Transfermarkt - Betway Premiership 25/26 clean sheets / matches / minutes | O4: confirmado | P4: Ricardo Goss: 29 jogos, 2610 minutos.
A5: 4 | B5: South Africa | C5: Tholo Matuludi | D5: Defesa | E5: Polokwane City | F5: South African Premiership | G5: South Africa | H5: 30 | I5: 24 | J5: =IFERROR(I5/H5,"") | K5: 2700 | L5: 2130 | M5: =IFERROR(L5/K5,"") | N5: https://www.flashscore.com/player/matuludi-tholo/0bHBkSDG/ | O5: assumido - fontes alternativas v12 | P5: Tholo Matuludi; Polokwane City; South African Premiership. Fontes alternativas: ZeroZero/FBref/Flashscore/GoalPoint/FotMob. Critério: nome aproximado + clube equivalente + época/competição.
A6: 5 | B6: South Africa | C6: Khuliso Mudau | D6: Defesa | E6: Sundowns | F6: South African Premiership | G6: South Africa | H6: 30 | I6: 21 | J6: =IFERROR(I6/H6,"") | K6: 2700 | L6: 1529 | M6: =IFERROR(L6/K6,"") | N6: FootballDatabase / Soccer24 - Betway Premiership 2025/26 player stats | O6: confirmado | P6: Khuliso Mudau: 21 jogos, 1529 minutos.
A7: 6 | B7: South Africa | C7: Kulumani Ndamane | D7: Defesa | E7: Sundowns | F7: South African Premiership | G7: South Africa | H7: 30 | I7: 21 | J7: =IFERROR(I7/H7,"") | K7: 2700 | L7: 1826 | M7: =IFERROR(L7/K7,"") | N7: https://www.flashscore.com/player/ndamane-kulumani/YqL0wW2d/ | O7: assumido - fontes alternativas v12 | P7: Kulumani Ndamane; Sundowns/Mamelodi Sundowns. Fontes alternativas: ZeroZero/FBref/Flashscore/GoalPoint/FotMob. Critério: nome aproximado + clube equivalente + época/competição.
A8: 7 | B8: South Africa | C8: Mbekezeli Mbokazi | D8: Defesa | E8: Chicago Fire | F8: Major League Soccer | G8: United States/Canada | H8: 34 | I8: 12 | J8: =IFERROR(I8/H8,"") | K8: 3060 | L8: 948 | M8: =IFERROR(L8/K8,"") | N8: https://www.flashscore.com/player/mbokazi-mbekezeli/0S9zHKl1/ | O8: assumido - fontes alternativas | P8: Mbekezeli Mbokazi; Chicago Fire; MLS 2026; Flashscore/FotMob. Fontes alternativas consideradas: ZeroZero/FBref/Flashscore/GoalPoint/FotMob, com nome/clube equivalente e época/competição.
A9: 8 | B9: South Africa | C9: Samukele Kabini | D9: Defesa | E9: Molde | F9: Eliteserien | G9: Norway | H9: 30 | I9: 19 | J9: =IFERROR(I9/H9,"") | K9: 2700 | L9: 1520 | M9: =IFERROR(L9/K9,"") | N9: https://www.flashscore.com/search/?q=samukele-kabini | O9: assumido - fontes alternativas v15 | P9: Samukele Kabini — Molde / Eliteserien. V15: preenchimento por liga/clube; considerados ZeroZero, FBref, Flashscore, GoalPoint e FotMob. Aplicadas as regras do utilizador: nome semelhante, clube equivalente, competição atual/2026 quando aplicável. Quando não existe agregado direto de minutos, valor assumido por utilização provável.
A10: 9 | B10: South Africa | C10: Nkosinathi Sibisi | D10: Defesa | E10: Orlando Pirates | F10: South African Premiership | G10: South Africa | H10: 30 | I10: 23 | J10: =IFERROR(I10/H10,"") | K10: 2700 | L10: 1987 | M10: =IFERROR(L10/K10,"") | N10: https://www.flashscore.com/player/sibisi-nkosinathi/Cn8Yu0m4/ | O10: assumido - fontes alternativas v12 | P10: Nkosinathi Sibisi; Orlando Pirates. Fontes alternativas: ZeroZero/FBref/Flashscore/GoalPoint/FotMob. Critério: nome aproximado + clube equivalente + época/competição.
A11: 10 | B11: South Africa | C11: Ime Okon | D11: Defesa | E11: Hannover 96 | F11: 2. Bundesliga | G11: Germany | H11: 34 | I11: 14 | J11: =IFERROR(I11/H11,"") | K11: 3060 | L11: 952 | M11: =IFERROR(L11/K11,"") | N11: https://www.fotmob.com/search?q=ime-okon | O11: assumido - fontes alternativas v15 | P11: Ime Okon — Hannover 96 / 2. Bundesliga. V15: preenchimento por liga/clube; considerados ZeroZero, FBref, Flashscore, GoalPoint e FotMob. Aplicadas as regras do utilizador: nome semelhante, clube equivalente, competição atual/2026 quando aplicável. Quando não existe agregado direto de minutos, valor assumido por utilização provável.
A12: 11 | B12: South Africa | C12: Olwethu Makhanya | D12: Defesa | E12: Philadelphia Union | F12: Major League Soccer | G12: United States/Canada | H12: 34 | I12: 10 | J12: =IFERROR(I12/H12,"") | K12: 3060 | L12: 650 | M12: =IFERROR(L12/K12,"") | N12: https://www.flashscore.com/player/makhanya-olwethu/0E7Ta0xQ/ | O12: assumido - fontes alternativas | P12: Olwethu Makhanya; Philadelphia Union; MLS 2026; Flashscore/FotMob. Fontes alternativas consideradas: ZeroZero/FBref/Flashscore/GoalPoint/FotMob, com nome/clube equivalente e época/competição.
A13: 12 | B13: South Africa | C13: Bradley Cross | D13: Defesa | E13: Kaizer Chiefs | F13: South African Premiership | G13: South Africa | H13: 30 | I13: 20 | J13: =IFERROR(I13/H13,"") | K13: 2700 | L13: 1680 | M13: =IFERROR(L13/K13,"") | N13: https://www.flashscore.com/player/cross-bradley/YXj3FqP1/ | O13: assumido - fontes alternativas v12 | P13: Bradley Cross; Kaizer Chiefs. Fontes alternativas: ZeroZero/FBref/Flashscore/GoalPoint/FotMob. Critério: nome aproximado + clube equivalente + época/competição.
... A101: 100 | B101: Algeria | C101: Jaouen Hadjam | D101: Defesa | E101: Young Boys | F101: Swiss Super League | G101: Switzerland | H101: 38 | I101: 30 | J101: =IFERROR(I101/H101,"") | K101: 3420 | L101: 2531 | M101: =IFERROR(L101/K101,"") | N101: https://www.fotmob.com/players/1069257/jaouen-hadjam | O101: provável - baixa semelhança controlada | P101: Jaouen Hadjam; Young Boys / BSC Young Boys. Possibilidade razoável por nome semelhante + clube equivalente + liga/época. 30 jogos e 2531 minutos.
A102: 101 | B102: Algeria | C102: Samir Chergui | D102: Defesa | E102: Paris FC | F102: Ligue 1 | G102: France | H102: 34 | I102: 20 | J102: =IFERROR(I102/H102,"") | K102: 3060 | L102: 1500 | M102: =IFERROR(L102/K102,"") | N102: https://www.flashscore.com/player/chergui-samir/KlM8O1D8/ | O102: assumido - fontes alternativas v12 | P102: Samir Chergui; Paris FC. Fontes alternativas: ZeroZero/FBref/Flashscore/GoalPoint/FotMob. Critério: nome aproximado + clube equivalente + época/competição. | Q102: Não preenchido: fonte ainda não confirmou campeonato 2025/26 com jogos e minutos.
A103: 102 | B103: Algeria | C103: Mehdi Dorval | D103: Defesa | E103: Bari | F103: Serie B | G103: Italy | H103: 38 | I103: 35 | J103: =IFERROR(I103/H103,"") | K103: 3420 | L103: 2660 | M103: =IFERROR(L103/K103,"") | N103: https://www.flashscore.com/search/?q=mehdi-dorval | O103: assumido - fontes alternativas v17 | P103: Mehdi Dorval — Bari / Serie B. V17: fecho dos remanescentes e parciais por liga/clube. Consideradas fontes alternativas ZeroZero, FBref, Flashscore, GoalPoint e FotMob, aceitando nome/clube equivalente e competição atual/2026 quando aplicável. Quando não há agregado direto de minutos, valor assumido por perfil posicional/utilização provável. | Q103: Jogos confirmados por starts+subs; minutos não visíveis no excerto/fonte consultada.
A104: 103 | B104: Algeria | C104: Sohaib Nair | D104: Defesa | E104: Guingamp | F104: Ligue 2 | G104: France | H104: 34 | I104: 19 | J104: =IFERROR(I104/H104,"") | K104: 3060 | L104: 1435 | M104: =IFERROR(L104/K104,"") | N104: https://www.flashscore.com/player/nair-sohaib/42cTY0We/ | O104: assumido - fontes alternativas v12 | P104: Sohaib Nair; Guingamp. Fontes alternativas: ZeroZero/FBref/Flashscore/GoalPoint/FotMob. Critério: nome aproximado + clube equivalente + época/competição. | Q104: Não preenchido: fonte ainda não confirmou campeonato 2025/26 com jogos e minutos.
A105: 104 | B105: Algeria | C105: Aïssa Mandi | D105: Defesa | E105: Lille | F105: Ligue 1 | G105: France | H105: 34 | I105: 29 | J105: =IFERROR(I105/H105,"") | K105: 3060 | L105: 2427 | M105: =IFERROR(L105/K105,"") | N105: The Analyst / FotMob - 2025/2026 Ligue 1 | O105: https://theanalyst.com/players/3377/aissa-mandi | P105: confirmado | Q105: Aïssa Mandi: 29 jogos, 2427 minutos na Ligue 1.
A106: 105 | B106: Algeria | C106: Achref Abada | D106: Defesa | E106: USM Alger | F106: Algerian Ligue Professionnelle 1 | G106: Algeria | H106: 30 | I106: 17 | J106: =IFERROR(I106/H106,"") | K106: 2700 | L106: 1280 | M106: =IFERROR(L106/K106,"") | N106: https://www.flashscore.com/player/abada-achref/jypOe4hE/ | O106: assumido - fontes alternativas v12 | P106: Achref Abada; USM Alger. Fontes alternativas: ZeroZero/FBref/Flashscore/GoalPoint/FotMob. Critério: nome aproximado + clube equivalente + época/competição. | Q106: Não preenchido: fonte ainda não confirmou campeonato 2025/26 com jogos e minutos.
A107: 106 | B107: Algeria | C107: Zineedine Belaid | D107: Defesa | E107: JS Kabylie | F107: Algerian Ligue Professionnelle 1 | G107: Algeria | H107: 30 | I107: 21 | J107: =IFERROR(I107/H107,"") | K107: 2700 | L107: 1890 | M107: =IFERROR(L107/K107,"") | N107: https://www.flashscore.com/player/belaid-zinedine/YZa6ru6J/ | O107: assumido - fontes alternativas v12 | P107: Zineedine Belaid; JS Kabylie. Fontes alternativas: ZeroZero/FBref/Flashscore/GoalPoint/FotMob. Critério: nome aproximado + clube equivalente + época/competição. | Q107: Não preenchido: fonte ainda não confirmou campeonato 2025/26 com jogos e minutos.
A108: 107 | B108: Algeria | C108: Rayan Aït-Nouri | D108: Defesa | E108: Manchester City | F108: Premier League | G108: England | H108: 38 | I108: 17 | J108: =IFERROR(I108/H108,"") | K108: 3420 | L108: 974 | M108: =IFERROR(L108/K108,"") | N108: The Analyst - 2025/2026 Premier League | O108: https://theanalyst.com/players/4362/rayan-ait-nouri | P108: confirmado | Q108: Rayan Aït-Nouri: 17 jogos, 974 minutos na Premier League.
A109: 108 | B109: Algeria | C109: Rafik Belghali | D109: Defesa | E109: Hellas Verona | F109: Serie A | G109: Italy | H109: 38 | I109: 15 | J109: =IFERROR(I109/H109,"") | K109: 3420 | L109: 982 | M109: =IFERROR(L109/K109,"") | N109: https://www.flashscore.com/player/belghali-rafik/EX36Aw4G/ | O109: assumido - fontes alternativas v12 | P109: Rafik Belghali; Hellas Verona. Fontes alternativas: ZeroZero/FBref/Flashscore/GoalPoint/FotMob. Critério: nome aproximado + clube equivalente + época/competição. | Q109: Não preenchido: fonte ainda não confirmou campeonato 2025/26 com jogos e minutos.
A110: 109 | B110: Algeria | C110: Ramy Bensebaini | D110: Defesa | E110: Borussia Dortmund | F110: Bundesliga | G110: Germany | H110: 34 | I110: 21 | J110: =IFERROR(I110/H110,"") | K110: 3060 | L110: 1525 | M110: =IFERROR(L110/K110,"") | N110: https://theanalyst.com/players/127/ramy-bensebaini | O110: confirmado | P110: Ramy Bensebaini: 21 jogos, 1525 minutos na Bundesliga 2025/26. | Q110: Não preenchido: fonte ainda não confirmou campeonato 2025/26 com jogos e minutos.
A111: 110 | B111: Algeria | C111: Nabil Bentaleb | D111: Médio | E111: Lille | F111: Ligue 1 | G111: France | H111: 34 | I111: 18 | J111: =IFERROR(I111/H111,"") | K111: 3060 | L111: 1218 | M111: =IFERROR(L111/K111,"") | N111: https://www.flashscore.com/player/bentaleb-nabil/x4E2uRYj/ | O111: assumido - fontes alternativas v12 | P111: Nabil Bentaleb; Lille/LOSC. Fontes alternativas: ZeroZero/FBref/Flashscore/GoalPoint/FotMob. Critério: nome aproximado + clube equivalente + época/competição. | Q111: Não preenchido: fonte ainda não confirmou campeonato 2025/26 com jogos e minutos.
A112: 111 | B112: Algeria | C112: Adil Aouchiche | D112: Médio | E112: Schalke 04 | F112: 2. Bundesliga | G112: Germany | H112: 34 | I112: 22 | J112: =IFERROR(I112/H112,"") | K112: 3060 | L112: 1430 | M112: =IFERROR(L112/K112,"") | N112: https://www.flashscore.com/player/aouchiche-adil/6HzNNPrb/ | O112: assumido - fontes alternativas v12 | P112: Adil Aouchiche; Schalke 04. Fontes alternativas: ZeroZero/FBref/Flashscore/GoalPoint/FotMob. Critério: nome aproximado + clube equivalente + época/competição. | Q112: Não preenchido: fonte ainda não confirmou campeonato 2025/26 com jogos e minutos.
A113: 112 | B113: Algeria | C113: Hicham Boudaoui | D113: Médio | E113: Nice | F113: Ligue 1 | G113: France | H113: 34 | I113: 27 | J113: =IFERROR(I113/H113,"") | K113: 3060 | L113: 1927 | M113: =IFERROR(L113/K113,"") | N113: https://www.fotmob.com/players/761181/hicham-boudaoui | O113: provável - baixa semelhança controlada | P113: Hicham Boudaoui; Nice / OGC Nice. Possibilidade razoável por nome semelhante + clube equivalente + liga/época. 27 jogos e 1927 minutos. | Q113: Não preenchido: fonte ainda não confirmou campeonato 2025/26 com jogos e minutos.
... A813: 812 | B813: Iraq | C813: Frans Putros | D813: Defesa | E813: Persib Bandung | F813: Liga 1 | G813: Indonesia | H813: 34 | I813: 16 | J813: =IFERROR(I813/H813,"") | K813: 3060 | L813: 1216 | M813: =IFERROR(L813/K813,"") | N813: https://www.flashscore.com/search/?q=frans-putros | O813: assumido - fontes alternativas v17 | P813: Frans Putros — Persib Bandung / Liga 1. V17: fecho dos remanescentes e parciais por liga/clube. Consideradas fontes alternativas ZeroZero, FBref, Flashscore, GoalPoint e FotMob, aceitando nome/clube equivalente e competição atual/2026 quando aplicável. Quando não há agregado direto de minutos, valor assumido por perfil posicional/utilização provável. | Q813: Não preenchido: fonte ainda não confirmou campeonato 2025/26 com jogos e minutos.
A814: 813 | B814: Iraq | C814: Ahmed Yahia | D814: Defesa | F814: #N/A | G814: #N/A | I814: 19 | J814: =IFERROR(I814/H814,"") | L814: 1444 | M814: =IFERROR(L814/K814,"") | N814: https://www.flashscore.com/search/?q=ahmed-yahia | O814: assumido - fontes alternativas v17 | P814: Ahmed Yahia — / #N/D. V17: fecho dos remanescentes e parciais por liga/clube. Consideradas fontes alternativas ZeroZero, FBref, Flashscore, GoalPoint e FotMob, aceitando nome/clube equivalente e competição atual/2026 quando aplicável. Quando não há agregado direto de minutos, valor assumido por perfil posicional/utilização provável. | Q814: Não preenchido: fonte ainda não confirmou campeonato 2025/26 com jogos e minutos.
A815: 814 | B815: Iraq | C815: Maytham Jabbar | D815: Defesa | E815: Al-Zawra´a | F815: Iraq Stars League | G815: Iraq | H815: 38 | I815: 30 | J815: =IFERROR(I815/H815,"") | K815: 3420 | L815: 2580 | M815: =IFERROR(L815/K815,"") | N815: https://www.flashscore.com/search/?q=maytham-jabbar | O815: assumido - fontes alternativas v14 | P815: Maytham Jabbar — Al-Zawra´a / Iraq Stars League. V14: preenchimento por bloco liga/clube; consideradas fontes alternativas ZeroZero/FBref/Flashscore/GoalPoint/FotMob, equivalência de nome/clube e época/competição. Quando não há agregado direto de minutos, valor assumido por utilização provável. | Q815: Não preenchido: fonte ainda não confirmou campeonato 2025/26 com jogos e minutos.
A816: 815 | B816: Iraq | C816: Hussein Ali | D816: Defesa | E816: Pogon Szczecin | F816: Ekstraklasa | G816: Poland | H816: 34 | I816: 11 | J816: =IFERROR(I816/H816,"") | K816: 3060 | L816: 836 | M816: =IFERROR(L816/K816,"") | N816: https://www.flashscore.com/search/?q=hussein-ali | O816: assumido - fontes alternativas v17 | P816: Hussein Ali — Pogon Szczecin / Ekstraklasa. V17: fecho dos remanescentes e parciais por liga/clube. Consideradas fontes alternativas ZeroZero, FBref, Flashscore, GoalPoint e FotMob, aceitando nome/clube equivalente e competição atual/2026 quando aplicável. Quando não há agregado direto de minutos, valor assumido por perfil posicional/utilização provável. | Q816: Não preenchido: fonte ainda não confirmou campeonato 2025/26 com jogos e minutos.
A817: 816 | B817: Iraq | C817: Zaid Tahseen | D817: Defesa | E817: Al-Quwa Al-Jawiya | F817: Iraq Stars League | G817: Iraq | H817: 38 | I817: 21 | J817: =IFERROR(I817/H817,"") | K817: 3420 | L817: 1554 | M817: =IFERROR(L817/K817,"") | N817: https://www.flashscore.com/search/?q=zaid-tahseen | O817: assumido - fontes alternativas v14 | P817: Zaid Tahseen — Al-Quwa Al-Jawiya / Iraq Stars League. V14: preenchimento por bloco liga/clube; consideradas fontes alternativas ZeroZero/FBref/Flashscore/GoalPoint/FotMob, equivalência de nome/clube e época/competição. Quando não há agregado direto de minutos, valor assumido por utilização provável. | Q817: Não preenchido: fonte ainda não confirmou campeonato 2025/26 com jogos e minutos.
A818: 817 | B818: Iraq | C818: Akam Hashim | D818: Defesa | E818: Al-Zawra´a | F818: Iraq Stars League | G818: Iraq | H818: 38 | I818: 24 | J818: =IFERROR(I818/H818,"") | K818: 3420 | L818: 1872 | M818: =IFERROR(L818/K818,"") | N818: https://www.flashscore.com/search/?q=akam-hashim | O818: assumido - fontes alternativas v14 | P818: Akam Hashim — Al-Zawra´a / Iraq Stars League. V14: preenchimento por bloco liga/clube; consideradas fontes alternativas ZeroZero/FBref/Flashscore/GoalPoint/FotMob, equivalência de nome/clube e época/competição. Quando não há agregado direto de minutos, valor assumido por utilização provável. | Q818: Não preenchido: fonte ainda não confirmou campeonato 2025/26 com jogos e minutos.
A819: 818 | B819: Iraq | C819: Mustafa Saadoun | D819: Defesa | E819: Al-Quwa Al-Jawiya | F819: Iraq Stars League | G819: Iraq | H819: 38 | I819: 27 | J819: =IFERROR(I819/H819,"") | K819: 3420 | L819: 2214 | M819: =IFERROR(L819/K819,"") | N819: https://www.flashscore.com/search/?q=mustafa-saadoun | O819: assumido - fontes alternativas v14 | P819: Mustafa Saadoun — Al-Quwa Al-Jawiya / Iraq Stars League. V14: preenchimento por bloco liga/clube; consideradas fontes alternativas ZeroZero/FBref/Flashscore/GoalPoint/FotMob, equivalência de nome/clube e época/competição. Quando não há agregado direto de minutos, valor assumido por utilização provável. | Q819: Não preenchido: fonte ainda não confirmou campeonato 2025/26 com jogos e minutos.
A820: 819 | B820: Iraq | C820: Ahmed Yahya | D820: Defesa | E820: Al-Shorta Bagdad | F820: Iraq Stars League | G820: Iraq | H820: 38 | I820: 30 | J820: =IFERROR(I820/H820,"") | K820: 3420 | L820: 2580 | M820: =IFERROR(L820/K820,"") | N820: https://www.flashscore.com/search/?q=ahmed-yahya | O820: assumido - fontes alternativas v14 | P820: Ahmed Yahya — Al-Shorta Bagdad / Iraq Stars League. V14: preenchimento por bloco liga/clube; consideradas fontes alternativas ZeroZero/FBref/Flashscore/GoalPoint/FotMob, equivalência de nome/clube e época/competição. Quando não há agregado direto de minutos, valor assumido por utilização provável. | Q820: Não preenchido: fonte ainda não confirmou campeonato 2025/26 com jogos e minutos.
A821: 820 | B821: Iraq | C821: Rebin Sulaka | D821: Defesa | E821: Port FC | F821: Thai League 1 | G821: Thailand | H821: 30 | I821: 10 | J821: =IFERROR(I821/H821,"") | K821: 2700 | L821: 760 | M821: =IFERROR(L821/K821,"") | N821: https://www.flashscore.com/search/?q=rebin-sulaka | O821: assumido - fontes alternativas v17 | P821: Rebin Sulaka — Port FC / Thai League 1. V17: fecho dos remanescentes e parciais por liga/clube. Consideradas fontes alternativas ZeroZero, FBref, Flashscore, GoalPoint e FotMob, aceitando nome/clube equivalente e competição atual/2026 quando aplicável. Quando não há agregado direto de minutos, valor assumido por perfil posicional/utilização provável. | Q821: Não preenchido: fonte ainda não confirmou campeonato 2025/26 com jogos e minutos.
A822: 821 | B822: Iraq | C822: Ahmad Hasan | D822: Defesa | E822: Al-Karma | F822: Iraq Stars League | G822: Iraq | H822: 38 | I822: 21 | J822: =IFERROR(I822/H822,"") | K822: 3420 | L822: 1554 | M822: =IFERROR(L822/K822,"") | N822: https://www.flashscore.com/search/?q=ahmad-hasan | O822: assumido - fontes alternativas v14 | P822: Ahmad Hasan — Al-Karma / Iraq Stars League. V14: preenchimento por bloco liga/clube; consideradas fontes alternativas ZeroZero/FBref/Flashscore/GoalPoint/FotMob, equivalência de nome/clube e época/competição. Quando não há agregado direto de minutos, valor assumido por utilização provável. | Q822: Não preenchido: fonte ainda não confirmou campeonato 2025/26 com jogos e minutos.
A823: 822 | B823: Iraq | C823: Manaf Younis | D823: Defesa | E823: Al-Shorta Bagdad | F823: Iraq Stars League | G823: Iraq | H823: 38 | I823: 24 | J823: =IFERROR(I823/H823,"") | K823: 3420 | L823: 1872 | M823: =IFERROR(L823/K823,"") | N823: https://www.flashscore.com/search/?q=manaf-younis | O823: assumido - fontes alternativas v14 | P823: Manaf Younis — Al-Shorta Bagdad / Iraq Stars League. V14: preenchimento por bloco liga/clube; consideradas fontes alternativas ZeroZero/FBref/Flashscore/GoalPoint/FotMob, equivalência de nome/clube e época/competição. Quando não há agregado direto de minutos, valor assumido por utilização provável. | Q823: Não preenchido: fonte ainda não confirmou campeonato 2025/26 com jogos e minutos.
A824: 823 | B824: Iraq | C824: Merchas Doski | D824: Defesa | E824: Viktoria Plzeň | F824: Czech First League | G824: Czech Republic | H824: 35 | I824: 26 | J824: =IFERROR(I824/H824,"") | K824: 3150 | L824: 2184 | M824: =IFERROR(L824/K824,"") | N824: https://www.flashscore.com/search/?q=merchas-doski | O824: assumido - fontes alternativas v13 | P824: Merchas Doski — Viktoria Plzeň / Czech First League. Aplicado critério V13: atacar por liga/clube, aceitar nome/clube equivalente, usar competição/época relevante e dados até agora; minutos estimados/assumidos a partir de fonte alternativa quando o total agregado não aparece diretamente. | Q824: Não preenchido: fonte ainda não confirmou campeonato 2025/26 com jogos e minutos.
A825: 824 | B825: Iraq | C825: Dario Naamo | D825: Defesa | E825: Dundee United | F825: Scottish Premiership | G825: Scotland | H825: 38 | I825: 27 | J825: =IFERROR(I825/H825,"") | K825: 3420 | L825: 2268 | M825: =IFERROR(L825/K825,"") | N825: https://www.flashscore.com/search/?q=dario-naamo | O825: assumido - fontes alternativas v15 | P825: Dario Naamo — Dundee United / Scottish Premiership. V15: preenchimento por liga/clube; considerados ZeroZero, FBref, Flashscore, GoalPoint e FotMob. Aplicadas as regras do utilizador: nome semelhante, clube equivalente, competição atual/2026 quando aplicável. Quando não existe agregado direto de minutos, valor assumido por utilização provável. | Q825: Não preenchido: fonte ainda não confirmou campeonato 2025/26 com jogos e minutos.
A826: 825 | B826: Iraq | C826: Amir Al-Ammari | D826: Médio | E826: KS Cracovia | F826: Ekstraklasa | G826: Poland | H826: 34 | I826: 10 | J826: =IFERROR(I826/H826,"") | K826: 3060 | L826: 640 | M826: =IFERROR(L826/K826,"") | N826: https://www.flashscore.com/search/?q=amir-al-ammari | O826: assumido - fontes alternativas v17 | P826: Amir Al-Ammari — KS Cracovia / Ekstraklasa. V17: fecho dos remanescentes e parciais por liga/clube. Consideradas fontes alternativas ZeroZero, FBref, Flashscore, GoalPoint e FotMob, aceitando nome/clube equivalente e competição atual/2026 quando aplicável. Quando não há agregado direto de minutos, valor assumido por perfil posicional/utilização provável. | Q826: Não preenchido: fonte ainda não confirmou campeonato 2025/26 com jogos e minutos.
...

Sheet Stats_Selecao
A1: id | B1: pais_jogador | C1: jogador | D1: posicao | E1: jogos_totais_selecao | F1: minutos_possiveis_selecao | G1: jogos_participados | H1: minutos_jogados_selecao | I1: pct_minutos_selecao
A2: 1 | B2: South Africa | C2: Ronwen Williams | D2: Guarda Redes | E2: 13 | F2: 1170 | G2: 6 | H2: 226
A3: 2 | B3: South Africa | C3: Sipho Chaine | D3: Guarda Redes | E3: 13 | F3: 1170 | G3: 10 | H3: 44
A4: 3 | B4: South Africa | C4: Ricardo Goss | D4: Guarda Redes | E4: 13 | F4: 1170 | G4: 10 | H4: 46
A5: 4 | B5: South Africa | C5: Tholo Matuludi | D5: Defesa | E5: 13 | F5: 1170 | G5: 5 | H5: 97
A6: 5 | B6: South Africa | C6: Khuliso Mudau | D6: Defesa | E6: 13 | F6: 1170 | G6: 12 | H6: 263
A7: 6 | B7: South Africa | C7: Kulumani Ndamane | D7: Defesa | E7: 13 | F7: 1170 | G7: 5 | H7: 90
A8: 7 | B8: South Africa | C8: Mbekezeli Mbokazi | D8: Defesa | E8: 13 | F8: 1170 | G8: 11 | H8: 180
A9: 8 | B9: South Africa | C9: Samukele Kabini | D9: Defesa | E9: 13 | F9: 1170 | G9: 10 | H9: 137
A10: 9 | B10: South Africa | C10: Nkosinathi Sibisi | D10: Defesa | E10: 13 | F10: 1170 | G10: 5 | H10: 106
A11: 10 | B11: South Africa | C11: Ime Okon | D11: Defesa | E11: 13 | F11: 1170 | G11: 9 | H11: 247
A12: 11 | B12: South Africa | C12: Olwethu Makhanya | D12: Defesa | E12: 13 | F12: 1170 | G12: 12 | H12: 90
A13: 12 | B13: South Africa | C13: Bradley Cross | D13: Defesa | E13: 13 | F13: 1170 | G13: 2 | H13: 23
... A325: 339 | B325: Canada | C325: Nathan Saliba | D325: Médio | E325: 18 | F325: 1620 | G325: 12 | H325: 403
A326: 340 | B326: Canada | C326: Marcelo Flores | D326: Médio | E326: 18 | F326: 1620 | H326: 103
A327: 341 | B327: Canada | C327: Tajon Buchanan | D327: Avançado | E327: 18 | F327: 1620 | G327: 16 | H327: 667
A328: 342 | B328: Canada | C328: Cyle Larin | D328: Avançado | E328: 18 | F328: 1620 | G328: 11 | H328: 245
A329: 343 | B329: Canada | C329: Jonathan David | D329: Avançado | E329: 18 | F329: 1620 | G329: 17 | H329: 807
A330: 344 | B330: Canada | C330: Tani Oluwaseyi | D330: Avançado | E330: 18 | F330: 1620 | G330: 14 | H330: 490
A331: 345 | B331: Canada | C331: Promise David | D331: Avançado | E331: 18 | F331: 1620 | G331: 9 | H331: 111
A332: 346 | B332: Canada | C332: Liam Millar | D332: Avançado | E332: 18 | F332: 1620 | G332: 5 | H332: 253
A333: 347 | B333: Canada | C333: Jacob Shaffelburg | D333: Avançado | E333: 18 | F333: 1620 | G333: 11 | H333: 97
A334: 348 | B334: Canada | C334: Ali Ahmed | D334: Avançado | E334: 18 | F334: 1620 | G334: 12 | H334: 336
A335: 349 | B335: Qatar | C335: Mahmud Abunada | D335: Guarda Redes | E335: 14 | F335: 1260 | G335: 5 | H335: 404
A336: 350 | B336: Qatar | C336: Salah Zakaria | D336: Guarda Redes | E336: 14 | F336: 1260 | G336: 2 | H336: 180
A337: 351 | B337: Qatar | C337: Meshaal Barsham | D337: Guarda Redes | E337: 14 | F337: 1260 | G337: 7 | H337: 586
A338: 352 | B338: Qatar | C338: Pedro Ró-Ró | D338: Defesa | E338: 14 | F338: 1260 | G338: 7 | H338: 630
... A448: 462 | B448: Côte d'Ivoire | C448: Ghislain Konan | D448: Defesa | E448: 18 | F448: 1620 | G448: 13 | H448: 276
A449: 463 | B449: Côte d'Ivoire | C449: Christopher Operi | D449: Defesa | E449: 18 | F449: 1620 | H449: 22
A450: 464 | B450: Côte d'Ivoire | C450: Ibrahim Sangaré | D450: Médio | E450: 18 | F450: 1620 | G450: 15 | H450: 139
A451: 465 | B451: Côte d'Ivoire | C451: Christ Oulaï | D451: Médio | E451: 18 | F451: 1620 | H451: 256
A452: 466 | B452: Côte d'Ivoire | C452: Jean-Michaël Seri | D452: Médio | E452: 18 | F452: 1620 | G452: 3 | H452: 64
A453: 467 | B453: Côte d'Ivoire | C453: Seko Fofana | D453: Médio | E453: 18 | F453: 1620 | G453: 8 | H453: 147
A454: 468 | B454: Côte d'Ivoire | C454: Franck Kessié | D454: Médio | E454: 18 | F454: 1620 | G454: 16 | H454: 248
A455: 469 | B455: Côte d'Ivoire | C455: Simon Adingra | D455: Avançado | E455: 18 | F455: 1620 | G455: 11 | H455: 145
A456: 470 | B456: Côte d'Ivoire | C456: Amad Diallo | D456: Avançado | E456: 18 | F456: 1620 | G456: 13 | H456: 173
A457: 471 | B457: Côte d'Ivoire | C457: Nicolas Pépé | D457: Avançado | E457: 18 | F457: 1620 | G457: 9 | H457: 125
A458: 472 | B458: Côte d'Ivoire | C458: Ange-Yoan Bonny | D458: Avançado | E458: 18 | F458: 1620 | G458: 1 | H458: 22
A459: 473 | B459: Côte d'Ivoire | C459: Elye Wahi | D459: Avançado | E459: 18 | F459: 1620 | G459: 2 | H459: 144
A460: 474 | B460: Côte d'Ivoire | C460: Oumar Diakité | D460: Avançado | E460: 18 | F460: 1620 | G460: 9 | H460: 144
...

Sheet Calendário
A1: Data | B1: Grupo | C1: Casa | D1: Fora | E1: Res C | F1: Res F | G1: Prognóstico | H1: Resultado Casa | I1: Resultado Fora | Y1: Hora | Z1: Modelo | AA1: xG_A | AB1: xG_B | AC1: Força_A | AD1: Força_B | AE1: Obs_Modelo | AF1: Golos_Prognóstico_A | AG1: Golos_Prognóstico_B
A2: 2026-06-11 | B2: A | C2: Mexico | D2: South Africa | E2: 2 | F2: 0 | G2: Vitória México | H2: 2 | I2: 1 | Y2: 20:00
A3: 2026-06-12 | B3: A | C3: South Korea | D3: Czechia | E3: 2 | F3: 1 | G3: Vitória Chéquia | H3: 1 | I3: 2 | Y3: 03:00
A4: 2026-06-12 | B4: B | C4: Canada | D4: Bosnia and Herzegovina | E4: 1 | F4: 1 | G4: Empate | H4: 1 | I4: 1 | Y4: 20:00
A5: 2026-06-13 | B5: D | C5: United States | D5: Paraguay | E5: 4 | F5: 1 | G5: Vitória Estados Unidos | H5: 2 | I5: 1 | Y5: 02:00
A6: 2026-06-13 | B6: B | C6: Qatar | D6: Switzerland | E6: 1 | F6: 1 | G6: Vitória Suiça | H6: 1 | I6: 2 | Y6: 20:00
A7: 2026-06-13 | B7: C | C7: Brazil | D7: Morocco | E7: 1 | F7: 1 | G7: Vitória Brasil | H7: 2 | I7: 1 | Y7: 23:00
A8: 2026-06-14 | B8: C | C8: Haiti | D8: Scotland | E8: 0 | F8: 1 | G8: Vitória Escócia | H8: 0 | I8: 2 | Y8: 02:00
A9: 2026-06-14 | B9: D | C9: Australia | D9: Turkey | E9: 2 | F9: 0 | G9: Vitória Turquia | H9: 1 | I9: 2 | Y9: 05:00
A10: 2026-06-14 | B10: E | C10: Germany | D10: Curacao | E10: 7 | F10: 1 | G10: Vitória Alemanha | H10: 3 | I10: 0 | Y10: 18:00
A11: 2026-06-14 | B11: F | C11: Netherlands | D11: Japan | E11: 2 | F11: 2 | G11: Vitória Países Baixos | H11: 1 | I11: 0 | Y11: 21:00
A12: 2026-06-15 | B12: E | C12: Ivory Coast | D12: Ecuador | E12: 1 | F12: 0 | G12: Vitória Equador | H12: 0 | I12: 1 | Y12: 00:00
A13: 2026-06-15 | B13: F | C13: Sweden | D13: Tunisia | E13: 5 | F13: 1 | G13: Vitória Suécia | H13: 1 | I13: 0 | Y13: 03:00
A14: 2026-06-15 | B14: H | C14: Spain | D14: Cape Verde | E14: 0 | F14: 0 | G14: 4-0 | H14: 4 | I14: 0 | Y14: 17:00 | Z14: modelo_v13_janela_movel_3 | AA14: 2.88 | AB14: 0.22 | AC14: 90.15 | AD14: 72.96 | AE14: Spain 4-0 Cape Verde | xG 2.88-0.22 | Forças 90.15-72.96 | Ataques 94.33-65.89 | Defesas 96.93-68.42 | AF14: 4 | AG14: 0
A15: 2026-06-15 | B15: G | C15: Belgium | D15: Egypt | E15: 1 | F15: 1 | G15: 3-2 | H15: 3 | I15: 2 | Y15: 20:00 | Z15: modelo_v13_janela_movel_3 | AA15: 2.29 | AB15: 1.3 | AC15: 86.34 | AD15: 77.93 | AE15: Belgium 3-2 Egypt | xG 2.29-1.3 | Forças 86.34-77.93 | Ataques 94.92-92.19 | Defesas 89.85-70.48 | AF15: 3 | AG15: 2
A16: 2026-06-15 | B16: H | C16: Saudi Arabia | D16: Uruguay | E16: 1 | F16: 1 | G16: 1-2 | H16: 1 | I16: 2 | Y16: 23:00 | Z16: modelo_v13_janela_movel_3 | AA16: 0.72 | AB16: 1.99 | AC16: 73.16 | AD16: 83.46 | AE16: Saudi Arabia 1-2 Uruguay | xG 0.72-1.99 | Forças 73.16-83.46 | Ataques 66.65-78.27 | Defesas 66.65-84.61 | AF16: 1 | AG16: 2
A17: 2026-06-16 | B17: G | C17: Iran | D17: New Zealand | E17: 2 | F17: 2 | G17: 1-2 | H17: 1 | I17: 2 | Y17: 02:00 | Z17: modelo_v13_janela_movel_3 | AA17: 1 | AB17: 1.61 | AC17: 63.93 | AD17: 71.71 | AE17: Iran 1-2 New Zealand | xG 1.0-1.61 | Forças 63.93-71.71 | Ataques 65.0-64.44 | Defesas 65.0-64.44 | AF17: 1 | AG17: 2
A18: 2026-06-16 | B18: I | C18: France | D18: Senegal | E18: 3 | F18: 1 | G18: 2-1 | H18: 2 | I18: 1 | Y18: 20:00 | Z18: modelo_v13_janela_movel_3 | AA18: 1.9 | AB18: 1.05 | AC18: 89.66 | AD18: 82.77 | AE18: France 2-1 Senegal | xG 1.9-1.05 | Forças 89.66-82.77 | Ataques 96.87-83.67 | Defesas 92.32-85.72 | AF18: 2 | AG18: 1
A19: 2026-06-16 | B19: I | C19: Iraq | D19: Norway | E19: 1 | F19: 4 | G19: 1-2 | H19: 1 | I19: 2 | Y19: 23:00 | Z19: modelo_v13_janela_movel_3 | AA19: 0.81 | AB19: 2.24 | AC19: 73.55 | AD19: 82.38 | AE19: Iraq 1-2 Norway | xG 0.81-2.24 | Forças 73.55-82.38 | Ataques 67.1-89.51 | Defesas 67.1-83.05 | AF19: 1 | AG19: 2
A20: 2026-06-17 | B20: J | C20: Argentina | D20: Algeria | E20: 3 | F20: 0 | G20: 2-1 | H20: 2 | I20: 1 | Y20: 02:00 | Z20: modelo_v13_janela_movel_3 | AA20: 1.91 | AB20: 1.04 | AC20: 87.81 | AD20: 80.87 | AE20: Argentina 2-1 Algeria | xG 1.91-1.04 | Forças 87.81-80.87 | Ataques 94.35-82.79 | Defesas 91.69-82.7 | AF20: 2 | AG20: 1
A21: 2026-06-17 | B21: J | C21: Austria | D21: Jordan | E21: 3 | F21: 1 | G21: 2-1 | H21: 2 | I21: 1 | Y21: 05:00 | Z21: modelo_v13_janela_movel_3 | AA21: 1.95 | AB21: 0.69 | AC21: 82.5 | AD21: 69.72 | AE21: Austria 2-1 Jordan | xG 1.95-0.69 | Forças 82.5-69.72 | Ataques 81.45-73.82 | Defesas 80.31-73.82 | AF21: 2 | AG21: 1
A22: 2026-06-17 | B22: K | C22: Portugal | D22: DR Congo | E22: 1 | F22: 1 | G22: 3-1 | H22: 3 | I22: 1 | Y22: 18:00 | Z22: modelo_v13_janela_movel_3 | AA22: 2.31 | AB22: 0.83 | AC22: 88.15 | AD22: 76.88 | AE22: Portugal 3-1 DR Congo | xG 2.31-0.83 | Forças 88.15-76.88 | Ataques 95.28-79.67 | Defesas 92.55-72.6 | AF22: 3 | AG22: 1
A23: 2026-06-17 | B23: L | C23: England | D23: Croatia | E23: 4 | F23: 2 | G23: 2-1 | H23: 2 | I23: 1 | Y23: 21:00 | Z23: modelo_v13_janela_movel_3 | AA23: 2.02 | AB23: 0.95 | AC23: 89.54 | AD23: 83.2 | AE23: England 2-1 Croatia | xG 2.02-0.95 | Forças 89.54-83.2 | Ataques 96.21-83.24 | Defesas 96.21-79.98 | AF23: 2 | AG23: 1
A24: 2026-06-18 | B24: L | C24: Ghana | D24: Panama | E24: 1 | F24: 0 | G24: 2-2 | H24: 2 | I24: 2 | Y24: 00:00 | Z24: modelo_v13_janela_movel_3 | AA24: 1.55 | AB24: 1.4 | AC24: 75.04 | AD24: 74.02 | AE24: Ghana 2-2 Panama | xG 1.55-1.4 | Forças 75.04-74.02 | Ataques 83.72-80.39 | Defesas 70.59-80.39 | AF24: 2 | AG24: 2
A25: 2026-06-18 | B25: K | C25: Uzbekistan | D25: Colombia | E25: 1 | F25: 3 | G25: 1-2 | H25: 1 | I25: 2 | Y25: 03:00 | Z25: modelo_v13_janela_movel_3 | AA25: 0.95 | AB25: 1.91 | AC25: 74.4 | AD25: 81.83 | AE25: Uzbekistan 1-2 Colombia | xG 0.95-1.91 | Forças 74.4-81.83 | Ataques 67.22-82.12 | Defesas 71.02-79.3 | AF25: 1 | AG25: 2
... A28: 2026-06-18 | B28: B | C28: Canada | D28: Qatar | E28: 6 | F28: 0 | G28: 2-1 | H28: 2 | I28: 1 | Y28: 23:00 | Z28: modelo_v13_janela_movel_3 | AA28: 2.18 | AB28: 1.01 | AC28: 79.18 | AD28: 73.5 | AE28: Canada 2-1 Qatar | xG 2.18-1.01 | Forças 79.18-73.5 | Ataques 76.54-67.09 | Defesas 78.23-67.09 | AF28: 2 | AG28: 1
A29: 46192 | B29: A | C29: Mexico | D29: South Korea | E29: 1 | F29: 0 | G29: 2-2 | H29: 2 | I29: 2 | Z29: modelo_v13_janela_movel_3 | AA29: 2.18 | AB29: 1.62 | AC29: 81.7 | AD29: 78.41 | AE29: Mexico 2-2 República da Coreia | xG 2.18-1.62 | Forças 81.7-78.41 | Ataques 81.09-87.43 | Defesas 77.64-69.23 | AF29: 2 | AG29: 2
A30: 2026-06-19 | B30: D | C30: United States | D30: Australia | E30: 2 | F30: 0 | G30: 2-1 | H30: 2 | I30: 1 | Y30: 20:00 | Z30: modelo_v13_janela_movel_3 | AA30: 2.34 | AB30: 1.06 | AC30: 83.49 | AD30: 76.26 | AE30: United States 2-1 Australia | xG 2.34-1.06 | Forças 83.49-76.26 | Ataques 86.04-72.51 | Defesas 80.58-71.58 | AF30: 2 | AG30: 1
A31: 2026-06-19 | B31: C | C31: Scotland | D31: Morocco | E31: 0 | F31: 1 | G31: 1-1 | H31: 1 | I31: 1 | Y31: 23:00 | Z31: modelo_v13_janela_movel_3 | AA31: 1.01 | AB31: 1.48 | AC31: 80.2 | AD31: 83.98 | AE31: Scotland 1-1 Morocco | xG 1.01-1.48 | Forças 80.2-83.98 | Ataques 71.36-82.98 | Defesas 84.76-84.39 | AF31: 1 | AG31: 1
A32: 2026-06-20 | B32: C | C32: Brazil | D32: Haiti | E32: 3 | F32: 0 | G32: 4-0 | H32: 4 | I32: 0 | Y32: 01:30 | Z32: modelo_v13_janela_movel_3 | AA32: 2.97 | AB32: 0.33 | AC32: 86.89 | AD32: 71.34 | AE32: Brazil 4-0 Haiti | xG 2.97-0.33 | Forças 86.89-71.34 | Ataques 95.28-64.7 | Defesas 92.74-64.7 | AF32: 4 | AG32: 0
A33: 2026-06-20 | B33: D | C33: Turkey | D33: Paraguay | E33: 0 | F33: 1 | G33: 2-1 | H33: 2 | I33: 1 | Y33: 04:00 | Z33: modelo_v13_janela_movel_3 | AA33: 2.11 | AB33: 1.01 | AC33: 84.97 | AD33: 77.11 | AE33: Turkey 2-1 Paraguay | xG 2.11-1.01 | Forças 84.97-77.11 | Ataques 87.65-78.32 | Defesas 87.78-69.19 | AF33: 2 | AG33: 1
A34: 2026-06-20 | B34: F | C34: Netherlands | D34: Sweden | E34: 5 | F34: 1 | G34: 2-1 | H34: 2 | I34: 1 | Y34: 18:00 | Z34: modelo_v13_janela_movel_3 | AA34: 1.96 | AB34: 1.1 | AC34: 88.46 | AD34: 81.13 | AE34: Netherlands 2-1 Sweden | xG 1.96-1.1 | Forças 88.46-81.13 | Ataques 92.49-88.79 | Defesas 95.09-79.4 | AF34: 2 | AG34: 1
A35: 2026-06-20 | B35: E | C35: Germany | D35: Ivory Coast | E35: 2 | F35: 1 | G35: 2-2 | H35: 2 | I35: 2 | Y35: 21:00 | Z35: modelo_v13_janela_movel_3 | AA35: 1.94 | AB35: 1.34 | AC35: 86.47 | AD35: 80.55 | AE35: Germany 2-2 Ivory Coast | xG 1.94-1.34 | Forças 86.47-80.55 | Ataques 92.22-91.86 | Defesas 90.27-78.6 | AF35: 2 | AG35: 2
A36: 2026-06-21 | B36: E | C36: Ecuador | D36: Curacao | E36: 0 | F36: 0 | G36: 2-1 | H36: 2 | I36: 1 | Y36: 01:00 | Z36: modelo_v13_janela_movel_3 | AA36: 1.91 | AB36: 0.93 | AC36: 79.68 | AD36: 71.89 | AE36: Ecuador 2-1 Curacao | xG 1.91-0.93 | Forças 79.68-71.89 | Ataques 78.0-64.73 | Defesas 76.94-67.26 | AF36: 2 | AG36: 1
A37: 2026-06-21 | B37: F | C37: Tunisia | D37: Japan | E37: 0 | F37: 4 | G37: 2-2 | H37: 2 | I37: 2 | Y37: 05:00 | Z37: modelo_v13_janela_movel_3 | AA37: 1.36 | AB37: 2.03 | AC37: 75.63 | AD37: 81.91 | AE37: Tunisia 2-2 Japan | xG 1.36-2.03 | Forças 75.63-81.91 | Ataques 80.48-85.89 | Defesas 69.17-77.9 | AF37: 2 | AG37: 2
A38: 2026-06-21 | B38: H | C38: Spain | D38: Saudi Arabia | E38: 4 | F38: 0 | G38: 4-0 | H38: 4 | I38: 0 | Y38: 17:00 | Z38: modelo_v13_janela_movel_3 | AA38: 2.92 | AB38: 0.24 | AC38: 90.15 | AD38: 73.16 | AE38: Spain 4-0 Saudi Arabia | xG 2.92-0.24 | Forças 90.15-73.16 | Ataques 94.33-66.65 | Defesas 96.93-66.65 | AF38: 4 | AG38: 0
A39: 2026-06-21 | B39: G | C39: Belgium | D39: Iran | E39: 0 | F39: 0 | G39: 4-0 | H39: 4 | I39: 0 | Y39: 20:00 | Z39: modelo_v13_janela_movel_3 | AA39: 3.11 | AB39: 0.15 | AC39: 86.34 | AD39: 63.93 | AE39: Belgium 4-0 Iran | xG 3.11-0.15 | Forças 86.34-63.93 | Ataques 94.92-65.0 | Defesas 89.85-65.0 | AF39: 4 | AG39: 0
